Workbook

Sheet Criteria_Manual
A1: Criterion | B1: Name | C1: Score 1 Rule | D1: Score 0 Rule
A2: Q1 | B2: Time-Bound Net-Zero Target | C2: 1 = explicit company net-zero target + target year | D2: 0 = generic/national ambition or no company target year
A3: Q2 | B3: Measurable Interim Emissions-Reduction Target | C3: 1 = quantitative interim emissions target + target year + baseline/reference | D3: 0 = qualitative/incomplete target
A4: Q3 | B4: SBTi-Validated Target | C4: 1 = official SBTi validation applies to observation year | D4: 0 = aligned/committed/planned/pending or no validation
A5: Q4 | B5: Quantitative Scope 1 and Scope 2 Disclosure | C5: 1 = numerical Scope 1 AND Scope 2 with unit/reporting period | D5: 0 = one scope only or insufficient quantitative disclosure
A6: Q5 | B6: Quantitative Scope 3 Disclosure | C6: 1 = numerical Scope 3 total/material category; financed emissions may qualify for banks | D6: 0 = discussion without quantitative disclosure
A7: Q6 | B7: Comparable Multi-Year Emissions Data | C7: 1 = at least 2 comparable years of relevant emissions data | D7: 0 = single year or materially non-comparable
A8: Q7 | B8: Transition Implementation & Resource Allocation | C8: 1 = concrete transition action linked to measurable financial/operational resources | D8: 0 = generic activity without resource/implementation evidence
A9: Q8 | B9: Board-Level Climate Oversight | C9: 1 = board or board-level committee explicitly oversees climate | D9: 0 = management-only or no explicit board responsibility
A10: Q9 | B10: Measurable Progress Against Targets | C10: 1 = quantitative actual performance compared with target/baseline/pathway/prior period | D10: 0 = no measurable target/progress comparison
A11: Q10 | B11: Independent External Assurance | C11: 1 = independent assurance covers relevant GHG/climate/sustainability data | D11: 0 = financial audit only or no relevant assurance

Sheet Official_Report_Sources
A1: Ticker | B1: Company | C1: Country | D1: Annual/One Report Hub | E1: Sustainability/Climate Hub | F1: 2022 | G1: 2023 | H1: 2024 | I1: 2025 | J1: Notes
A2: PTT | B2: PTT Public Company Limited | C2: Thailand | D2: https://investor.pttplc.com/en/downloads/yearly-reports | E2: https://www.pttplc.com/en/sustainability | F2: Download from official hub | G2: Download from official hub | H2: Download from official hub | I2: Download from official hub
A3: PTTEP | B3: PTT Exploration and Production Public Company Limited | C3: Thailand | D3: https://www.pttep.com/en/investor-relations/document/annual-reports | E3: https://sustainability.pttep.com/en/document/sustainability-reports | F3: Download from official hub | G3: Download from official hub | H3: Download from official hub | I3: Download from official hub
A4: GPSC | B4: Global Power Synergy Public Company Limited | C4: Thailand | D4: https://www.gpscgroup.com/en/investor-relations/downloads/one-reports | E4: https://www.gpscgroup.com/en/downloads/sd-report | F4: Download from official hub | G4: Download from official hub | H4: Download from official hub | I4: Download from official hub
A5: GULF | B5: Gulf Development / predecessor GULF | C5: Thailand | D5: https://sustainability.gulf.co.th/en/document/sustainability-reports | E5: https://sustainability.gulf.co.th/en/document/sustainability-reports/archive | F5: Download from official hub | G5: Download from official hub | H5: Download from official hub | I5: Download from official hub
A6: KBANK | B6: Kasikornbank Public Company Limited | C6: Thailand | D6: https://www.kasikornbank.com/en/ir/finaninforeports/pages/financial-reports.aspx | E6: https://www.kasikornbank.com/en/sustainable-development/Pages/goals.aspx | F6: Download from official hub | G6: Download from official hub | H6: Download from official hub | I6: Download from official hub
A7: SCBX | B7: SCB X Public Company Limited | C7: Thailand | D7: https://www.scbx.com/en/investor-relations/ | E7: https://www.scbx.com/th/sustainability/report-and-disclosures/ | F7: Download from official hub | G7: Download from official hub | H7: Download from official hub | I7: Download from official hub
A8: SCC | B8: The Siam Cement Public Company Limited (SCG) | C8: Thailand | D8: https://scc.listedcompany.com/ | E8: https://www.scgsustainability.com/en/ | F8: Download from official hub | G8: Download from official hub | H8: Download from official hub | I8: Download from official hub
A9: CPALL | B9: CP ALL Public Company Limited | C9: Thailand | D9: https://www.cpall.co.th/en/investor/news-publications/publication/annual-report/ | E9: https://www.cpall.co.th/sustain/sd-report/ | F9: Download from official hub | G9: Download from official hub | H9: Download from official hub | I9: Download from official hub
A10: CPN | B10: Central Pattana Public Company Limited | C10: Thailand | D10: https://investor.centralpattana.co.th/ | E10: https://sustainability.centralpattana.co.th/en/document/sustainability-reports | F10: Download from official hub | G10: Download from official hub | H10: Download from official hub | I10: Download from official hub
A11: ADVANC | B11: Advanced Info Service Public Company Limited (AIS) | C11: Thailand | D11: https://investor.ais.co.th/en/document/annual-reports | E11: https://sustainability.ais.co.th/ | F11: Download from official hub | G11: Download from official hub | H11: Download from official hub | I11: Download from official hub
A12: BCP | B12: Bangchak Corporation Public Company Limited | C12: Thailand | D12: https://investor.bangchak.co.th/en/document/annual-reports | E12: https://investor.bangchak.co.th/en/resource-center | F12: Download from official hub | G12: Download from official hub | H12: Download from official hub | I12: Download from official hub
A13: AOT | B13: Airports of Thailand Public Company Limited | C13: Thailand | D13: https://investor.airportthai.co.th/download.html | E13: https://corporatestrategy.airportthai.co.th/en/sd/sd-report/ | F13: Download from official hub | G13: Download from official hub | H13: Download from official hub | I13: Download from official hub
... A20: MAERSK | B20: A.P. Moller - Maersk A/S | C20: Denmark | D20: https://investor.maersk.com/financials/annual-reports | E20: https://www.maersk.com/sustainability/reports-and-resources | F20: Download from official hub | G20: Download from official hub | H20: Download from official hub | I20: Download from official hub
A21: HOLCIM | B21: Holcim Ltd | C21: Switzerland | D21: https://www.holcim.com/investors/publications | E21: https://www.holcim.com/sustainability/esg/esg-policies-documents-reports | F21: Download from official hub | G21: Download from official hub | H21: Download from official hub | I21: Download from official hub | J21: Official Holcim archive lists reports for 2022, 2023, 2024 and 2025. Use the Integrated Annual Report plus Climate/Sustainability materials for each year.

Sheet PDF_Download_Manifest
A1: Ticker | B1: Year | C1: Type | D1: Priority | E1: What to Download | F1: Official Hub | G1: Suggested Filename | H1: Downloaded? | I1: Checked? | J1: Notes
A2: PTT | B2: 2022 | C2: Annual / One Report | D2: CORE | E2: Annual Report / Form 56-1 One Report covering this observation year | F2: https://investor.pttplc.com/en/downloads/yearly-reports | G2: PTT_2022_Annual_OneReport.pdf | H2: No | I2: No
A3: PTT | B3: 2022 | C3: Sustainability / Climate | D3: CORE | E3: Sustainability / ESG / Climate report covering this observation year | F3: https://www.pttplc.com/en/sustainability | G3: PTT_2022_Sustainability_Climate.pdf | H3: No | I3: No
A4: PTT | B4: 2022 | C4: Assurance / Data / Transition Plan | D4: SUPPLEMENT | E4: Separate assurance, ESG data book, TCFD/IFRS S2 or transition plan if the main report does not contain the evidence | F4: https://www.pttplc.com/en/sustainability | G4: PTT_2022_Supplement.pdf | H4: No | I4: No | J4: Only download if separate/relevant
A5: PTT | B5: 2023 | C5: Annual / One Report | D5: CORE | E5: Annual Report / Form 56-1 One Report covering this observation year | F5: https://investor.pttplc.com/en/downloads/yearly-reports | G5: PTT_2023_Annual_OneReport.pdf | H5: No | I5: No
A6: PTT | B6: 2023 | C6: Sustainability / Climate | D6: CORE | E6: Sustainability / ESG / Climate report covering this observation year | F6: https://www.pttplc.com/en/sustainability | G6: PTT_2023_Sustainability_Climate.pdf | H6: No | I6: No
A7: PTT | B7: 2023 | C7: Assurance / Data / Transition Plan | D7: SUPPLEMENT | E7: Separate assurance, ESG data book, TCFD/IFRS S2 or transition plan if the main report does not contain the evidence | F7: https://www.pttplc.com/en/sustainability | G7: PTT_2023_Supplement.pdf | H7: No | I7: No | J7: Only download if separate/relevant
A8: PTT | B8: 2024 | C8: Annual / One Report | D8: CORE | E8: Annual Report / Form 56-1 One Report covering this observation year | F8: https://investor.pttplc.com/en/downloads/yearly-reports | G8: PTT_2024_Annual_OneReport.pdf | H8: No | I8: No
A9: PTT | B9: 2024 | C9: Sustainability / Climate | D9: CORE | E9: Sustainability / ESG / Climate report covering this observation year | F9: https://www.pttplc.com/en/sustainability | G9: PTT_2024_Sustainability_Climate.pdf | H9: No | I9: No
A10: PTT | B10: 2024 | C10: Assurance / Data / Transition Plan | D10: SUPPLEMENT | E10: Separate assurance, ESG data book, TCFD/IFRS S2 or transition plan if the main report does not contain the evidence | F10: https://www.pttplc.com/en/sustainability | G10: PTT_2024_Supplement.pdf | H10: No | I10: No | J10: Only download if separate/relevant
A11: PTT | B11: 2025 | C11: Annual / One Report | D11: CORE | E11: Annual Report / Form 56-1 One Report covering this observation year | F11: https://investor.pttplc.com/en/downloads/yearly-reports | G11: PTT_2025_Annual_OneReport.pdf | H11: No | I11: No
A12: PTT | B12: 2025 | C12: Sustainability / Climate | D12: CORE | E12: Sustainability / ESG / Climate report covering this observation year | F12: https://www.pttplc.com/en/sustainability | G12: PTT_2025_Sustainability_Climate.pdf | H12: No | I12: No
A13: PTT | B13: 2025 | C13: Assurance / Data / Transition Plan | D13: SUPPLEMENT | E13: Separate assurance, ESG data book, TCFD/IFRS S2 or transition plan if the main report does not contain the evidence | F13: https://www.pttplc.com/en/sustainability | G13: PTT_2025_Supplement.pdf | H13: No | I13: No | J13: Only download if separate/relevant
A14: PTTEP | B14: 2022 | C14: Annual / One Report | D14: CORE | E14: Annual Report / Form 56-1 One Report covering this observation year | F14: https://www.pttep.com/en/investor-relations/document/annual-reports | G14: PTTEP_2022_Annual_OneReport.pdf | H14: No | I14: No
A15: PTTEP | B15: 2022 | C15: Sustainability / Climate | D15: CORE | E15: Sustainability / ESG / Climate report covering this observation year | F15: https://sustainability.pttep.com/en/document/sustainability-reports | G15: PTTEP_2022_Sustainability_Climate.pdf | H15: No | I15: No
A16: PTTEP | B16: 2022 | C16: Assurance / Data / Transition Plan | D16: SUPPLEMENT | E16: Separate assurance, ESG data book, TCFD/IFRS S2 or transition plan if the main report does not contain the evidence | F16: https://sustainability.pttep.com/en/document/sustainability-reports | G16: PTTEP_2022_Supplement.pdf | H16: No | I16: No | J16: Only download if separate/relevant
A17: PTTEP | B17: 2023 | C17: Annual / One Report | D17: CORE | E17: Annual Report / Form 56-1 One Report covering this observation year | F17: https://www.pttep.com/en/investor-relations/document/annual-reports | G17: PTTEP_2023_Annual_OneReport.pdf | H17: No | I17: No
A18: PTTEP | B18: 2023 | C18: Sustainability / Climate | D18: CORE | E18: Sustainability / ESG / Climate report covering this observation year | F18: https://sustainability.pttep.com/en/document/sustainability-reports | G18: PTTEP_2023_Sustainability_Climate.pdf | H18: No | I18: No
A19: PTTEP | B19: 2023 | C19: Assurance / Data / Transition Plan | D19: SUPPLEMENT | E19: Separate assurance, ESG data book, TCFD/IFRS S2 or transition plan if the main report does not contain the evidence | F19: https://sustainability.pttep.com/en/document/sustainability-reports | G19: PTTEP_2023_Supplement.pdf | H19: No | I19: No | J19: Only download if separate/relevant
A20: PTTEP | B20: 2024 | C20: Annual / One Report | D20: CORE | E20: Annual Report / Form 56-1 One Report covering this observation year | F20: https://www.pttep.com/en/investor-relations/document/annual-reports | G20: PTTEP_2024_Annual_OneReport.pdf | H20: No | I20: No
A21: PTTEP | B21: 2024 | C21: Sustainability / Climate | D21: CORE | E21: Sustainability / ESG / Climate report covering this observation year | F21: https://sustainability.pttep.com/en/document/sustainability-reports | G21: PTTEP_2024_Sustainability_Climate.pdf | H21: No | I21: No
A22: PTTEP | B22: 2024 | C22: Assurance / Data / Transition Plan | D22: SUPPLEMENT | E22: Separate assurance, ESG data book, TCFD/IFRS S2 or transition plan if the main report does not contain the evidence | F22: https://sustainability.pttep.com/en/document/sustainability-reports | G22: PTTEP_2024_Supplement.pdf | H22: No | I22: No | J22: Only download if separate/relevant
A23: PTTEP | B23: 2025 | C23: Annual / One Report | D23: CORE | E23: Annual Report / Form 56-1 One Report covering this observation year | F23: https://www.pttep.com/en/investor-relations/document/annual-reports | G23: PTTEP_2025_Annual_OneReport.pdf | H23: No | I23: No
A24: PTTEP | B24: 2025 | C24: Sustainability / Climate | D24: CORE | E24: Sustainability / ESG / Climate report covering this observation year | F24: https://sustainability.pttep.com/en/document/sustainability-reports | G24: PTTEP_2025_Sustainability_Climate.pdf | H24: No | I24: No
A25: PTTEP | B25: 2025 | C25: Assurance / Data / Transition Plan | D25: SUPPLEMENT | E25: Separate assurance, ESG data book, TCFD/IFRS S2 or transition plan if the main report does not contain the evidence | F25: https://sustainability.pttep.com/en/document/sustainability-reports | G25: PTTEP_2025_Supplement.pdf | H25: No | I25: No | J25: Only download if separate/relevant
A26: GPSC | B26: 2022 | C26: Annual / One Report | D26: CORE | E26: Annual Report / Form 56-1 One Report covering this observation year | F26: https://www.gpscgroup.com/en/investor-relations/downloads/one-reports | G26: GPSC_2022_Annual_OneReport.pdf | H26: No | I26: No
A27: GPSC | B27: 2022 | C27: Sustainability / Climate | D27: CORE | E27: Sustainability / ESG / Climate report covering this observation year | F27: https://www.gpscgroup.com/en/downloads/sd-report | G27: GPSC_2022_Sustainability_Climate.pdf | H27: No | I27: No
A28: GPSC | B28: 2022 | C28: Assurance / Data / Transition Plan | D28: SUPPLEMENT | E28: Separate assurance, ESG data book, TCFD/IFRS S2 or transition plan if the main report does not contain the evidence | F28: https://www.gpscgroup.com/en/downloads/sd-report | G28: GPSC_2022_Supplement.pdf | H28: No | I28: No | J28: Only download if separate/relevant
A29: GPSC | B29: 2023 | C29: Annual / One Report | D29: CORE | E29: Annual Report / Form 56-1 One Report covering this observation year | F29: https://www.gpscgroup.com/en/investor-relations/downloads/one-reports | G29: GPSC_2023_Annual_OneReport.pdf | H29: No | I29: No
A30: GPSC | B30: 2023 | C30: Sustainability / Climate | D30: CORE | E30: Sustainability / ESG / Climate report covering this observation year | F30: https://www.gpscgroup.com/en/downloads/sd-report | G30: GPSC_2023_Sustainability_Climate.pdf | H30: No | I30: No
A31: GPSC | B31: 2023 | C31: Assurance / Data / Transition Plan | D31: SUPPLEMENT | E31: Separate assurance, ESG data book, TCFD/IFRS S2 or transition plan if the main report does not contain the evidence | F31: https://www.gpscgroup.com/en/downloads/sd-report | G31: GPSC_2023_Supplement.pdf | H31: No | I31: No | J31: Only download if separate/relevant
A32: GPSC | B32: 2024 | C32: Annual / One Report | D32: CORE | E32: Annual Report / Form 56-1 One Report covering this observation year | F32: https://www.gpscgroup.com/en/investor-relations/downloads/one-reports | G32: GPSC_2024_Annual_OneReport.pdf | H32: No | I32: No
A33: GPSC | B33: 2024 | C33: Sustainability / Climate | D33: CORE | E33: Sustainability / ESG / Climate report covering this observation year | F33: https://www.gpscgroup.com/en/downloads/sd-report | G33: GPSC_2024_Sustainability_Climate.pdf | H33: No | I33: No
A34: GPSC | B34: 2024 | C34: Assurance / Data / Transition Plan | D34: SUPPLEMENT | E34: Separate assurance, ESG data book, TCFD/IFRS S2 or transition plan if the main report does not contain the evidence | F34: https://www.gpscgroup.com/en/downloads/sd-report | G34: GPSC_2024_Supplement.pdf | H34: No | I34: No | J34: Only download if separate/relevant
A35: GPSC | B35: 2025 | C35: Annual / One Report | D35: CORE | E35: Annual Report / Form 56-1 One Report covering this observation year | F35: https://www.gpscgroup.com/en/investor-relations/downloads/one-reports | G35: GPSC_2025_Annual_OneReport.pdf | H35: No | I35: No
A36: GPSC | B36: 2025 | C36: Sustainability / Climate | D36: CORE | E36: Sustainability / ESG / Climate report covering this observation year | F36: https://www.gpscgroup.com/en/downloads/sd-report | G36: GPSC_2025_Sustainability_Climate.pdf | H36: No | I36: No
A37: GPSC | B37: 2025 | C37: Assurance / Data / Transition Plan | D37: SUPPLEMENT | E37: Separate assurance, ESG data book, TCFD/IFRS S2 or transition plan if the main report does not contain the evidence | F37: https://www.gpscgroup.com/en/downloads/sd-report | G37: GPSC_2025_Supplement.pdf | H37: No | I37: No | J37: Only download if separate/relevant
A38: GULF | B38: 2022 | C38: Annual / One Report | D38: CORE | E38: Annual Report / Form 56-1 One Report covering this observation year | F38: https://sustainability.gulf.co.th/en/document/sustainability-reports | G38: GULF_2022_Annual_OneReport.pdf | H38: No | I38: No
A39: GULF | B39: 2022 | C39: Sustainability / Climate | D39: CORE | E39: Sustainability / ESG / Climate report covering this observation year | F39: https://sustainability.gulf.co.th/en/document/sustainability-reports/archive | G39: GULF_2022_Sustainability_Climate.pdf | H39: No | I39: No
A40: GULF | B40: 2022 | C40: Assurance / Data / Transition Plan | D40: SUPPLEMENT | E40: Separate assurance, ESG data book, TCFD/IFRS S2 or transition plan if the main report does not contain the evidence | F40: https://sustainability.gulf.co.th/en/document/sustainability-reports/archive | G40: GULF_2022_Supplement.pdf | H40: No | I40: No | J40: Only download if separate/relevant
...

Sheet Coding_800
A1: Type | B1: Company | C1: Year | D1: Sector | E1: Criterion | F1: Criterion Name | G1: Assistant Proposed Score | H1: Assistant Coding Status | I1: Evidence Summary / Quote | J1: Report | K1: Page | L1: Source URL | M1: Researcher Checked Evidence? | N1: Researcher Coder 1 Score | O1: Score Used (Provisional until checked) | P1: Rationale / Notes
A2: Thai Main Sample | B2: PTT | C2: 2022 | D2: Energy | E2: Q1 | F2: Time-Bound Net-Zero Target | G2: 1 | H2: AI evidence found — researcher verification required | I2: a Platinum class award. This reflects PTT’s commitment to conducting business with • Awarded Attachment sustainable social and environmental responsibility to achieve June 2022 the goals of carbon neutrality in 2040 and Net Zero Emissions • Awarded by in 2050 through the 3Ps strategy, namely Pursuit of Lower Thailand Institute of Emissions to drive PTT Group’s greenhouse gas emissions PTT received a plaque of honor Occupational Safety PTT Metro Forest Learning Center reduction projects; Portfolio Transformation, adjustment and Health received an honorary award for the Workation Thailand project, of investment plans to the future energy business (Public Organization) from the TGDA 2022. “Work From Everywhere” at Gold level. and bey | J2: PTT one report 2022(1).pdf | K2: p. 11 | L2: https://www.pttplc.com/en/sustainability | M2: No | O2: =IF(N2<>"",N2,G2) -> 1 | P2: Explicit time-bound company net-zero target found. | AI-assisted evidence retrieval; not yet personally verified by the researcher.
A3: Thai Main Sample | B3: PTT | C3: 2022 | D3: Energy | E3: Q2 | F3: Measurable Interim Emissions-Reduction Target | G3: 0 | H3: AI preliminary 0/uncertain — researcher verification required | I3: ement of Revenue Net Income Financial Position Financial Ratios Vision, Mission and PTT Values PTT Information THB 3,367,203 THB 91,175 THB 3,415,632 million million million Financial Highlights Milestone Achievement +40% +49% +187% -16% +21% +11% Net Profit to Total Sales Revenue Awards and Recognition 3.63 (%) Message from the Board of Directors 3,367,203 108,363 1% 13% 3,415,632 Economic, Petroleum 3% Return on Equity 1,040,862 688,345 26% and Petrochemical Review and Outlook 3,071,384 (%) 91,175 8.85 3% 855,254 648,619 21% 22% Section 1 Business Operations and Performance 2,544,183 1,193,594 Return on 2,258,818 Total Assets 720,931 462,835 14% Section 2 949,825 1% 1% (%) 3.76 875,440 2% 1% Corporate Governance 30% 8% 8% 779,25 | J3: PTT one report 2022(1).pdf | K3: p. 6 | L3: https://www.pttplc.com/en/sustainability | M3: No | O3: =IF(N3<>"",N3,G3) -> 0 | P3: Quantitative target wording did not clearly contain all three required elements: magnitude, target year and baseline/reference point. | AI-assisted evidence retrieval; not yet personally verified by the researcher.
A4: Thai Main Sample | B4: PTT | C4: 2022 | D4: Energy | E4: Q3 | F4: SBTi-Validated Target | G4: 0 | H4: AI preliminary 0/uncertain — researcher verification required | I4: No explicit SBTi validation statement found in the selected reports. | J4: PTT one report 2022(1).pdf | L4: https://www.pttplc.com/en/sustainability | M4: No | O4: =IF(N4<>"",N4,G4) -> 0 | P4: No official SBTi validation applicable to the observation year was evidenced; alignment, commitment, submission or later validation does not qualify. | AI-assisted evidence retrieval; not yet personally verified by the researcher.
A5: Thai Main Sample | B5: PTT | C5: 2022 | D5: Energy | E5: Q4 | F5: Quantitative Scope 1 and Scope 2 Disclosure | G5: 0 | H5: AI preliminary 0/uncertain — researcher verification required | I5: No qualifying evidence found in selected report(s). | J5: PTT one report 2022(1).pdf | L5: https://www.pttplc.com/en/sustainability | M5: No | O5: =IF(N5<>"",N5,G5) -> 0 | P5: No qualifying evidence found under the strict coding rule. | AI-assisted evidence retrieval; not yet personally verified by the researcher.
A6: Thai Main Sample | B6: PTT | C6: 2022 | D6: Energy | E6: Q5 | F6: Quantitative Scope 3 Disclosure | G6: 0 | H6: AI preliminary 0/uncertain — researcher verification required | I6: No qualifying evidence found in selected report(s). | J6: PTT one report 2022(1).pdf | L6: https://www.pttplc.com/en/sustainability | M6: No | O6: =IF(N6<>"",N6,G6) -> 0 | P6: No qualifying evidence found under the strict coding rule. | AI-assisted evidence retrieval; not yet personally verified by the researcher.
A7: Thai Main Sample | B7: PTT | C7: 2022 | D7: Energy | E7: Q6 | F7: Comparable Multi-Year Emissions Data | G7: 0 | H7: AI preliminary 0/uncertain — researcher verification required | I7: 020 56-1 One Report 2022 021 56-1 One Report 2022 PTT Public Company Limited Awards and Recognition PTT Public Company Limited Awards and Recognition PTT received the Outstanding 56-1 One Report 2022 Organization Award from PTT Public Company Limited King Prajadhipok’s Institute Association. Governance His Excellency Chuan Leekpai, President of the National Assembly, presented a plaque of honor “Outstanding Organization Association of King Prajadhipok’s Institute” Contents PTT received the State Excellence for 2022 to Mr. Auttapol Rer | J7: PTT one report 2022(1).pdf | K7: p. 12 | L7: https://www.pttplc.com/en/sustainability | M7: No | O7: =IF(N7<>"",N7,G7) -> 0 | P7: A multi-year emissions series was not sufficiently evidenced on the selected disclosure. | AI-assisted evidence retrieval; not yet personally verified by the researcher.
A8: Thai Main Sample | B8: PTT | C8: 2022 | D8: Energy | E8: Q7 | F8: Transition Implementation & Resource Allocation | G8: 0 | H8: AI conservative 0 — evidence snippet did not satisfy all strict rule elements; researcher recheck recommended | I8: as transmission, international trading, new business Thailand Securities Depository Company Limited Sales and Service Revenue 1,615,665 2,258,818 3,367,203 Milestone Achievement and infrastructure business; the rest are invested through 93, 14th Floor, The Stock Exchange of Thailand Building, Earnings before Interest, subsidiaries joint arrangements and associates, and Ratchadaphisek Road, Din Daeng, Din Daeng, Awards and Recognition Taxes, Depreciation and Amortization (EBITDA) 225,672 427,956 491,288 PTT Group, namely exploration and production, liquefied Bangkok 10400, Thailand Message from the Board of Directors natural gas, petrochemical and refining, oil and retail, Telephone: 66 (0) 2009-9999 Profit attribute to Equity Hold | J8: PTT one report 2022(1).pdf | K8: p. 5 | L8: https://www.pttplc.com/en/sustainability | M8: No | O8: =IF(N8<>"",N8,G8) -> 0 | P8: Automated retrieval found a potentially relevant page, but the captured evidence did not contain all strict coding elements together. Conservatively coded 0 pending researcher verification.
A9: Thai Main Sample | B9: PTT | C9: 2022 | D9: Energy | E9: Q8 | F9: Board-Level Climate Oversight | G9: 1 | H9: AI evidence found — researcher verification required | I9: on 2 Corporate Governance Attachment Financial Highlights Milestone Achievement 004 Vision, Mission and PTT Values 041 1. Structure and Business Operations 229 6. Corporate Governance 367 Attachment 1 Information of the Board of Directors, Awards and Recognition 006 PTT Information of PTT Group 258 7. Governance Structure Executives, Controlling Persons Message from the Board of Directors 007 Financial Highlights 122 2. Risk Management and Key Data on the Board of Directors, and Company Secretary Economic, Petroleum 010 Milestone Achievement 134 3. Driving Business towards Sustainability Specific Committees, Management, 442 Attachment 2 and Petrochemical Review and Outlook Details of Directors and Subsidiaries 016 Awards and Recog | J9: PTT one report 2022(1).pdf | K9: p. 3 | L9: https://www.pttplc.com/en/sustainability | M9: No | O9: =IF(N9<>"",N9,G9) -> 1 | P9: Board or board-level committee has explicit oversight/responsibility for climate or sustainability matters. | AI-assisted evidence retrieval; not yet personally verified by the researcher.
A10: Thai Main Sample | B10: PTT | C10: 2022 | D10: Energy | E10: Q9 | F10: Measurable Progress Against Targets | G10: 0 | H10: AI preliminary 0/uncertain — researcher verification required | I10: ement of Revenue Net Income Financial Position Financial Ratios Vision, Mission and PTT Values PTT Information THB 3,367,203 THB 91,175 THB 3,415,632 million million million Financial Highlights Milestone Achievement +40% +49% +187% -16% +21% +11% Net Profit to Total Sales Revenue Awards and Recognition 3.63 (%) Message from the Board of Directors 3,367,203 108,363 1% 13% 3,415,632 Economic, Petroleum 3% Return on Equity 1,040,862 688,345 26% and Petrochemical Review and Outlook 3,071,384 (%) 91,175 8.85 3% 855,254 648,619 21% 22% Section 1 Business Operations and Performance 2,544,183 1,193,594 Return on 2,258,818 Total Assets 720,931 462,835 14% Section 2 949,825 1% 1% (%) 3.76 875,440 2% 1% Corporate Governance 30% 8% 8% 779,25 | J10: PTT one report 2022(1).pdf | K10: p. 6 | L10: https://www.pttplc.com/en/sustainability | M10: No | O10: =IF(N10<>"",N10,G10) -> 0 | P10: Quantitative emissions are present but measurable progress against a target/baseline/pathway was not sufficiently evidenced. | AI-assisted evidence retrieval; not yet personally verified by the researcher.
A11: Thai Main Sample | B11: PTT | C11: 2022 | D11: Energy | E11: Q10 | F11: Independent External Assurance | G11: 0 | H11: AI preliminary 0/uncertain — researcher verification required | I11: oard and Duties and Responsibilities of Specific Committees of PTT Public Section Company Limited Attachment Financial Report 445 Attachment 6 Report of the Audit Committee 446 About This Report 366 Financial Report 447 Assurance Report | J11: PTT one report 2022(1).pdf | K11: p. 3 | L11: https://www.pttplc.com/en/sustainability | M11: No | O11: =IF(N11<>"",N11,G11) -> 0 | P11: External audit/assurance language was found, but coverage of relevant GHG/climate data was not sufficiently clear. | AI-assisted evidence retrieval; not yet personally verified by the researcher.
A12: Thai Main Sample | B12: PTT | C12: 2023 | D12: Energy | E12: Q1 | F12: Time-Bound Net-Zero Target | G12: 0 | H12: AI conservative 0 — evidence snippet did not satisfy all strict rule elements; researcher recheck recommended | I12: nd the entire transportation network of the country. and local communities to form “Thailand’s Leading Society and Communities receiving terminal to increase ethane import capacity, Network towards Carbon Neutrality and Net Zero Goals”. 9. Internal Control and Connected (2) 19% in Natural Gas Transmission Pipeline 3) Being a “low-carbon and sustainable organization” This is for driving the participation of various sectors in Transaction Maintaining an excellent corporate standing in Thai society Business Unit, including Bang Pakong - South Bangkok ready to drive Thailand towards Net Zero: PTT Group has reducing greenhouse gas emissions, as well as speeding by exercising environmental stewardship of internationally Power Plant and | J12: PTT one report 2023.pdf | K12: p. 123 | L12: https://www.pttplc.com/en/sustainability | M12: No | O12: =IF(N12<>"",N12,G12) -> 0 | P12: Automated retrieval found a potentially relevant page, but the captured evidence did not contain all strict coding elements together. Conservatively coded 0 pending researcher verification.
A13: Thai Main Sample | B13: PTT | C13: 2023 | D13: Energy | E13: Q2 | F13: Measurable Interim Emissions-Reduction Target | G13: 1 | H13: AI evidence found — researcher verification required | I13: etitiveness information Governance 8.1 growth, and drive Enhancement 8.2 PTT Information and the economy Performance forward Financial Highlights Excellence Increasing renewable energy production capacity - 15 gigawatts by 2030 4.9 gigawatts Achievement Highlights Limiting PTT and PTT Group’s direct and indirect PTT Group: ≤ 51.5 million tons PTT Group: 15% reduction PTT Group: The 5th strategy: 6.6 14.2 17 greenhouse gas emissions (Scope 1 and 2) domestically of carbon dioxide equivalent by 2030 compared to the 2020 41.59 million tons of Eco-friendly Page 158 Awards and Recognition Developing the and internationally PTT: ≤ 11.5 million tons emissions carbon dioxide Development 7.1 15.2 business towards a 7.2 of carbon dioxide equ | J13: PTT one report 2023.pdf | K13: p. 72 | L13: https://www.pttplc.com/en/sustainability | M13: No | O13: =IF(N13<>"",N13,G13) -> 1 | P13: Quantitative interim reduction target includes target year and baseline/reference point. | AI-assisted evidence retrieval; not yet personally verified by the researcher.
A14: Thai Main Sample | B14: PTT | C14: 2023 | D14: Energy | E14: Q3 | F14: SBTi-Validated Target | G14: 0 | H14: AI preliminary 0/uncertain — researcher verification required | I14: 1 One Report 2023 PTT Public Company Limited August December August 2, 2022: August 17, 2022: December 15, 2022: Contents PTT International Holdings Limited (PTTIH) (a wholly owned The Energy Regulatory Commission (ERC) approved the criteria December 14, 2022: PTT Board of Directors approved the five-year (Year 2023 - 2027) PTT Board of Directors approved the shareholding subsidiary of PTT) has entered into a Share Purchase of natural gas tariff for natural gas transportation licensees investment plan of PTT and its wholly owned subsidiaries in Vision, Mission and PTT Values restructuring of AI & Robotics business by assigning SMH Agreement of its entire investment, being 100% of through pipeline, which consist of two components; | J14: PTT one report 2023.pdf | K14: p. 30 | L14: https://www.pttplc.com/en/sustainability | M14: No | O14: =IF(N14<>"",N14,G14) -> 0 | P14: No official SBTi validation applicable to the observation year was evidenced; alignment, commitment, submission or later validation does not qualify. | AI-assisted evidence retrieval; not yet personally verified by the researcher.
A15: Thai Main Sample | B15: PTT | C15: 2023 | D15: Energy | E15: Q4 | F15: Quantitative Scope 1 and Scope 2 Disclosure | G15: 1 | H15: AI evidence found — researcher verification required | I15: rting systems for market-based Scope 2 greenhouse gas emissions compared greenhouse gas emissions, absorption, and storage data, to the previous year. This increase was attributed to the Direct greenhouse gas emissions (scope 1)2, 3 43.47 47.27 45.39 40.73 Contents covering direct emissions (Scope 1), emissions from energy increased electricity purchases to meet the growing demand Biogenic CO2 emissions N/A N/A 0.004 7 0.007 Scope use (Scope 2), and other indirect emissions (Scope 3). from the expanded operational scope. Meanwhile, the volume 1&2 Indirect greenhouse gas emissions (scope 2) (location-based) 1.01 1.12 0.65 0.86 Vision, Mission and PTT Values These systems have been continuously improved to align of direct Scope 1 gr | J15: PTT one report 2023.pdf | K15: p. 85 | L15: https://www.pttplc.com/en/sustainability | M15: No | O15: =IF(N15<>"",N15,G15) -> 1 | P15: Quantitative Scope 1 and Scope 2 emissions are disclosed with numerical data. | AI-assisted evidence retrieval; not yet personally verified by the researcher.
A16: Thai Main Sample | B16: PTT | C16: 2023 | D16: Energy | E16: Q5 | F16: Quantitative Scope 3 Disclosure | G16: 1 | H16: AI evidence found — researcher verification required | I16: tents covering direct emissions (Scope 1), emissions from energy increased electricity purchases to meet the growing demand Biogenic CO2 emissions N/A N/A 0.004 7 0.007 Scope use (Scope 2), and other indirect emissions (Scope 3). from the expanded operational scope. Meanwhile, the volume 1&2 Indirect greenhouse gas emissions (scope 2) (location-based) 1.01 1.12 0.65 0.86 Vision, Mission and PTT Values These systems have been continuously improved to align of direct Scope 1 greenhouse gas emissions decreased from with international standards by enhancing methodologies, the previous year due to primary factors such as reduced Indirect greenhouse gas emissions (scope 2) (market-based) 2, 3 1.69 1.46 0.86 0.87 PTT Information operatio | J16: PTT one report 2023.pdf | K16: p. 85 | L16: https://www.pttplc.com/en/sustainability | M16: No | O16: =IF(N16<>"",N16,G16) -> 1 | P16: Quantitative Scope 3 emissions (including financed emissions where relevant) are disclosed. | AI-assisted evidence retrieval; not yet personally verified by the researcher.
A17: Thai Main Sample | B17: PTT | C17: 2023 | D17: Energy | E17: Q6 | F17: Comparable Multi-Year Emissions Data | G17: 0 | H17: AI conservative 0 — evidence snippet did not satisfy all strict rule elements; researcher recheck recommended | I17: rting systems for market-based Scope 2 greenhouse gas emissions compared greenhouse gas emissions, absorption, and storage data, to the previous year. This increase was attributed to the Direct greenhouse gas emissions (scope 1)2, 3 43.47 47.27 45.39 40.73 Contents covering direct emissions (Scope 1), emissions from energy increased electricity purchases to meet the growing demand Biogenic CO2 emissions N/A N/A 0.004 7 0.007 Scope use (Scope 2), and other indirect emissions (Scope 3). from the expanded operational scope. Meanwhile, the volume 1&2 Indirect greenhouse gas emissions (scope 2) (location-based) 1.01 1.12 0.65 0.86 Vision, Mission and PTT Values These systems have been continuously improved to align of direct Scope 1 gr | J17: PTT one report 2023.pdf | K17: p. 85 | L17: https://www.pttplc.com/en/sustainability | M17: No | O17: =IF(N17<>"",N17,G17) -> 0 | P17: Automated retrieval found a potentially relevant page, but the captured evidence did not contain all strict coding elements together. Conservatively coded 0 pending researcher verification.
A18: Thai Main Sample | B18: PTT | C18: 2023 | D18: Energy | E18: Q7 | F18: Transition Implementation & Resource Allocation | G18: 0 | H18: AI conservative 0 — evidence snippet did not satisfy all strict rule elements; researcher recheck recommended | I18: t (CFP). million of unrealized gain on fair value of commodity contracts, THB 5,479 million of gain on derivatives, THB 4,614 million Contents of gain on disposal of assets, and THB 3,013 million of share of profit from investments in joint ventures and associates and Vision, Mission and PTT Values Liabilities the change in net operating assets resulted in the increase in cash flow of THB 46,247 million while there were income taxes paid of THB 83,201 million. PTT Information As of December 31, 2023, PTT Group had total liabilities of THB 1,835,486 million, decreased by THB 46,453 million or Financial Highlights 2.5% from December 31, 2022, mainly from the followings; Net cash used in investing activities was THB 161,245 million m | J18: PTT one report 2023.pdf | K18: p. 106 | L18: https://www.pttplc.com/en/sustainability | M18: No | O18: =IF(N18<>"",N18,G18) -> 0 | P18: Automated retrieval found a potentially relevant page, but the captured evidence did not contain all strict coding elements together. Conservatively coded 0 pending researcher verification.
... A45: Thai Main Sample | B45: PTTEP | C45: 2022 | D45: Energy | E45: Q4 | F45: Quantitative Scope 1 and Scope 2 Disclosure | G45: 1 | H45: AI evidence found — researcher verification required | I45: has set a target to reduce GHG emissions intensity from our and (2) Application of various technologies to reduce E&P activities under PTTEP’s operational control covering GHG emissions from the production process, for Scope 1 and Scope 2 emissions by at least 25% within 2030 example, recovery flare gas or excess gas went back (from the base year 2012). Throughout the past decade, into the production process for further utilization, PTTEP was committed to continually reducing greenhouse energy efficiency improvement, production efficiency gas emissions (GHG emissions) through the implementation improvement, reduction of methane leak, adoption of various projects in both domestic and international assets. of renewable energy in op | J45: PTTEP sustainability report 2022.pdf | K45: p. 17 | L45: https://sustainability.pttep.com/en/document/sustainability-reports | M45: No | O45: =IF(N45<>"",N45,G45) -> 1 | P45: Quantitative Scope 1 and Scope 2 emissions are disclosed with numerical data. | AI-assisted evidence retrieval; not yet personally verified by the researcher.
A46: Thai Main Sample | B46: PTTEP | C46: 2022 | D46: Energy | E46: Q5 | F46: Quantitative Scope 3 Disclosure | G46: 0 | H46: AI preliminary 0/uncertain — researcher verification required | I46: No qualifying evidence found in selected report(s). | J46: PTTEP one report 2022.pdf | L46: https://sustainability.pttep.com/en/document/sustainability-reports | M46: No | O46: =IF(N46<>"",N46,G46) -> 0 | P46: No qualifying evidence found under the strict coding rule. | AI-assisted evidence retrieval; not yet personally verified by the researcher.
A47: Thai Main Sample | B47: PTTEP | C47: 2022 | D47: Energy | E47: Q6 | F47: Comparable Multi-Year Emissions Data | G47: 0 | H47: AI preliminary 0/uncertain — researcher verification required | I47: ation and Production and Production Production and Public Production Production Public Public Public Company Company Public Company Limited Limited Limited Company Company Limited Limited 56-1 One Report / Annual Report 2022 tes Notes Notes thetoNotes toNotes toto 424 the the Consolidated to the the Consolidated Consolidated Consolidated Consolidated PTT and and and Separate Exploration and Separate and Separate and SeparateFinancial Separate Financial Production Financial Public Statements Statements Statements Statements Statements Financial Financial Company Limited theFor r For For year theFor the year the the yearnded nded year nded year 31 December 31 December December 31 31 ended ended ended December 31 December 20222022 20 | J47: PTTEP one report 2022.pdf | K47: p. 420 | L47: https://sustainability.pttep.com/en/document/sustainability-reports | M47: No | O47: =IF(N47<>"",N47,G47) -> 0 | P47: A multi-year emissions series was not sufficiently evidenced on the selected disclosure. | AI-assisted evidence retrieval; not yet personally verified by the researcher.
A48: Thai Main Sample | B48: PTTEP | C48: 2022 | D48: Energy | E48: Q7 | F48: Transition Implementation & Resource Allocation | G48: 0 | H48: AI conservative 0 — evidence snippet did not satisfy all strict rule elements; researcher recheck recommended | I48: Participation Interest: 60% Participation Interest: 100% Operator: Eni Operator: Chevron Operator: PTTEP Group 1 On August 31, 2022, PTTEP Group has entered into a Sale and Purchase Agreement (SPA) to sell PTTEP Brazil Investments in Oil and Gas Exploration and 7 On March 14, 2022, PTTEP International Limited (PTTEPI), a wholly-owned subsidiary of PTTEP Group and a partner in the project, has assumed the operatorship Production Limitada, which holds 25% interest in the Barreirinhas AP1 Project and 20% interest in the Brazil BM-ES-23 Project. The completion will be subject of Yadana Project and Moattama Gas Transportation Company (MGTC), with effect from July 20, 2022. to conditions as prescribed in the SPA. 8 The concession of Co | J48: PTTEP sustainability report 2022.pdf | K48: p. 23 | L48: https://sustainability.pttep.com/en/document/sustainability-reports | M48: No | O48: =IF(N48<>"",N48,G48) -> 0 | P48: Automated retrieval found a potentially relevant page, but the captured evidence did not contain all strict coding elements together. Conservatively coded 0 pending researcher verification.
A49: Thai Main Sample | B49: PTTEP | C49: 2022 | D49: Energy | E49: Q8 | F49: Board-Level Climate Oversight | G49: 0 | H49: AI conservative 0 — evidence snippet did not satisfy all strict rule elements; researcher recheck recommended | I49: Governance Structure and Key Data on the Board of Directors, Specific Committees, Management, Employees, and Others 199 Form 56-1 One Report Year 2022 In 2022, the Company invested in human capital development programs at the total amount of THB 243,814,938 and provided more than 292,512 training and development hours for our employees with an average of 57 training and development hours per person per annum. PTTEP has a policy for management in implementing an Individual Competency Development Plan (ICDP) for PTTEP Staff. To ensure standardization, PTTEP | J49: PTTEP one report 2022.pdf | K49: p. 195 | L49: https://sustainability.pttep.com/en/document/sustainability-reports | M49: No | O49: =IF(N49<>"",N49,G49) -> 0 | P49: Automated retrieval found a potentially relevant page, but the captured evidence did not contain all strict coding elements together. Conservatively coded 0 pending researcher verification.
A50: Thai Main Sample | B50: PTTEP | C50: 2022 | D50: Energy | E50: Q9 | F50: Measurable Progress Against Targets | G50: 0 | H50: AI preliminary 0/uncertain — researcher verification required | I50: Structure and Business Operations 63 PTTEP 100% 75% 51% 20% 15% 50% 100% 49% 25% 49% PTT SPSE Energy PTTEP PTTEPI PTTEPO PTTEPS Digital Complex EH GHBR 25% PTTEP 75% Services 25% PTTEP 75% TC 100% 100% 100% 50% 100% 53.9496% 25.001% 100% 80% 37.0842% 100% 100% 100% 100% 100% 100% 25% PTTEP 75% PTTEP B8/32 PTTEP PTTEP PTTEP PTTEP PTTEP PTTEP PTTEP CPOC SHL Orange PTTEPH ATL MGTC EP-Tech BC HK G7 25% Partners SV KV HV HL AG ED 75% PTTEP 100% 100% 100% NH PTTEP 100% YS PTTEP PGH 50% Natuna 2 25% 28.5% 35% MENA HKO B.V. 100% 100% 100% 100% 100% 100% 100% HV JOC HL | J50: PTTEP one report 2022.pdf | K50: p. 59 | L50: https://sustainability.pttep.com/en/document/sustainability-reports | M50: No | O50: =IF(N50<>"",N50,G50) -> 0 | P50: Quantitative emissions are present but measurable progress against a target/baseline/pathway was not sufficiently evidenced. | AI-assisted evidence retrieval; not yet personally verified by the researcher.
A51: Thai Main Sample | B51: PTTEP | C51: 2022 | D51: Energy | E51: Q10 | F51: Independent External Assurance | G51: 0 | H51: AI preliminary 0/uncertain — researcher verification required | I51: opriateness. 9) Perform other duties relating to PTTEP risk management as may be assigned by the Board. The Risk Management Committee consists of at least 3 directors, while ensuring that at least one of them must be an independent director. As of December 31, 2022, the Committee comprised 4 members, 4 of which were independent directors as follows: Mr. Pitipan Tepartimargorn Chairman and Independent Director Lieutenant General Nimit Suwannarat Member and Independent Director Mr. Veerathai Santiprabhob Member and Independent Director Mr. Bundhit Eua-arporn Member and Independent Director Mr. Atikom Terbsiri has resigned from the positions of Director and Member of the Risk Management Committee. His resignation is effective from 30 | J51: PTTEP one report 2022.pdf | K51: p. 187 | L51: https://sustainability.pttep.com/en/document/sustainability-reports | M51: No | O51: =IF(N51<>"",N51,G51) -> 0 | P51: External audit/assurance language was found, but coverage of relevant GHG/climate data was not sufficiently clear. | AI-assisted evidence retrieval; not yet personally verified by the researcher.
A52: Thai Main Sample | B52: PTTEP | C52: 2023 | D52: Energy | E52: Q1 | F52: Time-Bound Net-Zero Target | G52: 1 | H52: AI evidence found — researcher verification required | I52: Building a Sustainable Tomorrow 261 9. Building a Sustainable Tomorrow 9.1 Striving towards Net Zero In 2023, PTTEP was able to reduce GHG emissions by more than 0.9 million tonnes of CO 2 equivalent. PTTEP acknowledges the critical business challenges posed This accomplishment results in a cumulative GHG reduction by the energy transition and the impacts of global warming of more than 2.4 million tonnes of CO2 equivalent since and climate change. Consequently, in 2022, the Company 2020. This is equivalent to CO2 absorption by 2.5 million announced our commitment through EP Net Zero 2050 rai of trees per | J52: PTTEP one report 2023.pdf | K52: p. 251 | L52: https://sustainability.pttep.com/en/document/sustainability-reports | M52: No | O52: =IF(N52<>"",N52,G52) -> 1 | P52: Explicit time-bound company net-zero target found. | AI-assisted evidence retrieval; not yet personally verified by the researcher.
A53: Thai Main Sample | B53: PTTEP | C53: 2023 | D53: Energy | E53: Q2 | F53: Measurable Interim Emissions-Reduction Target | G53: 0 | H53: AI preliminary 0/uncertain — researcher verification required | I53: PTTEP 100% 75% 51% 20% 15% 50% 100% 49% 25% 49% PTT PTT Energy PTTEP PTTEPI PTTEPO Siam Digital SPSE Complex EH GHBR 25% PTTEP 75% Structure and Business Operations Services 25% PTTEP 75% TC 50% 100% 53.9496% 25.001% 100% 80% 37.0842% 100% 100% 100% 100% 100% 100% 100% 100% 25% PTTEP 75% B8/32 PTTEP PTTEP PTTEP PTTEP PTTEP PTTEP PTTEP HK CPOC SHL Orange Partners PTTEPH ATL MGTC KV HV HL AG EP-Tech BC ED 25% SV 75% PTTEP 25% 28.5% 35% 100% NH 100% 100% PTTEP HV JOC HL JOC GBRS MENA PTTEP PGH HKO 50% Natuna 2 B.V. 100% 100% 1 | J53: PTTEP one report 2023.pdf | K53: p. 63 | L53: https://sustainability.pttep.com/en/document/sustainability-reports | M53: No | O53: =IF(N53<>"",N53,G53) -> 0 | P53: Quantitative target wording did not clearly contain all three required elements: magnitude, target year and baseline/reference point. | AI-assisted evidence retrieval; not yet personally verified by the researcher.
A54: Thai Main Sample | B54: PTTEP | C54: 2023 | D54: Energy | E54: Q3 | F54: SBTi-Validated Target | G54: 0 | H54: AI preliminary 0/uncertain — researcher verification required | I54: zero greenhouse gas emissions • Establish guidelines for the assessment of impacts related to the energy sector business such as ISO and of greenhouse gas emissions for GHG Criteria for Science Based Targets initiative (SBTi). These could affect Investment Decision Guidelines, including Internal the enforcement of greenhouse gas emission reductions Carbon Price that is used to consider new investment between the year and the target year 2050 and also offset projects. This is a tool to help assess the economic greenhouse gas emissions with specific types of carbon impact of new projects in relation to the Company’s credits, all of which may affect the Company’s operations. greenhouse gas emissions targets. Mitigation plan: PTTEP fo | J54: PTTEP one report 2023.pdf | K54: p. 95 | L54: https://sustainability.pttep.com/en/document/sustainability-reports | M54: No | O54: =IF(N54<>"",N54,G54) -> 0 | P54: No official SBTi validation applicable to the observation year was evidenced; alignment, commitment, submission or later validation does not qualify. | AI-assisted evidence retrieval; not yet personally verified by the researcher.
A55: Thai Main Sample | B55: PTTEP | C55: 2023 | D55: Energy | E55: Q4 | F55: Quantitative Scope 1 and Scope 2 Disclosure | G55: 1 | H55: AI evidence found — researcher verification required | I55: tegy, aiming to reach Net Zero Greenhouse Gas (GHG) through E&P portfolio management and the deployment of Emissions by 2050. This goal covers both direct emissions diverse technologies to reduce GHG emissions from the (Scope 1) and indirect emissions (Scope 2) of the exploration production process. Notable initiatives include flare gas and production business under PTTEP’s operational control. recovery and utilization, energy efficiency improvement, PTTEP has also set interim targets to reduce GHG emissions production efficiency enhancement, mitigation of methane intensity by at least 30 percent within 2030 and 50 percent leaks, and integration of renewable energy in operations within 2040 (from base year 2020). as well as effici | J55: PTTEP one report 2023.pdf | K55: p. 251 | L55: https://sustainability.pttep.com/en/document/sustainability-reports | M55: No | O55: =IF(N55<>"",N55,G55) -> 1 | P55: Quantitative Scope 1 and Scope 2 emissions are disclosed with numerical data. | AI-assisted evidence retrieval; not yet personally verified by the researcher.
A56: Thai Main Sample | B56: PTTEP | C56: 2023 | D56: Energy | E56: Q5 | F56: Quantitative Scope 3 Disclosure | G56: 0 | H56: AI preliminary 0/uncertain — researcher verification required | I56: No qualifying evidence found in selected report(s). | J56: PTTEP one report 2023.pdf | L56: https://sustainability.pttep.com/en/document/sustainability-reports | M56: No | O56: =IF(N56<>"",N56,G56) -> 0 | P56: No qualifying evidence found under the strict coding rule. | AI-assisted evidence retrieval; not yet personally verified by the researcher.
A57: Thai Main Sample | B57: PTTEP | C57: 2023 | D57: Energy | E57: Q6 | F57: Comparable Multi-Year Emissions Data | G57: 0 | H57: AI preliminary 0/uncertain — researcher verification required | I57: ancial Highlights 9 Contents Financial Highlights Message from Chairman and CEO Financial Highlights Total Assets Total Liabilities Total Equity Total Revenues Profit for the Year Financial Highlights (USD Million) 2021 2022 2023 Environmental, Social, Governance Dividend per Share (THB) 5.00 9.25 9.50* Highlight Performance 30,000 Dividend Yield (%)** 4.24 5.24 6.35 Value Creation * Total dividend of 2023 at the rate of THB 9.50 per share includes the interim dividend at the rate of THB 4.25 per share and the second half-year dividend at 26,380 the rate of THB 5.25 per share. Payments of the interim dividend and the second half-year dividend will be proposed in 2024 General Shareholder’s Meeting Stakeholders’ Voices 25,000 25,168 | J57: PTTEP one report 2023.pdf | K57: p. 6 | L57: https://sustainability.pttep.com/en/document/sustainability-reports | M57: No | O57: =IF(N57<>"",N57,G57) -> 0 | P57: A multi-year emissions series was not sufficiently evidenced on the selected disclosure. | AI-assisted evidence retrieval; not yet personally verified by the researcher.
A58: Thai Main Sample | B58: PTTEP | C58: 2023 | D58: Energy | E58: Q7 | F58: Transition Implementation & Resource Allocation | G58: 0 | H58: AI conservative 0 — evidence snippet did not satisfy all strict rule elements; researcher recheck recommended | I58: uishment. 6 In February 2023, PTTEP Group, along with Petronas Carigali Sdn Bhd. (PCSB), INPEX Cash Maple Pty Ltd and TotalEnergies Exploration Australia Pty Ltd. PTTEP AAA • On February 23, 2023, the sale of the entire investment in PTTEP Brazil Investments in However, all partners in the project remain obliged to decommissioning as prescribed and Petroleum Sarawak Exploration & Production Sdn Bhd. (PSEP) was awarded holds 100 percent interests in the retention lease and the divestment was completed on Oil and Gas Exploration and Production Limitada (PTTEP BL) which holds 25 percent by laws. the exploration Block SK325, which is located offshore of Sarawak, Malaysia. December 22, 2023. interest in the Barreirinhas AP1 Project and | J58: PTTEP one report 2023.pdf | K58: p. 35 | L58: https://sustainability.pttep.com/en/document/sustainability-reports | M58: No | O58: =IF(N58<>"",N58,G58) -> 0 | P58: Automated retrieval found a potentially relevant page, but the captured evidence did not contain all strict coding elements together. Conservatively coded 0 pending researcher verification.
A59: Thai Main Sample | B59: PTTEP | C59: 2023 | D59: Energy | E59: Q8 | F59: Board-Level Climate Oversight | G59: 0 | H59: AI conservative 0 — evidence snippet did not satisfy all strict rule elements; researcher recheck recommended | I59: Governance Structure and Key Data on the Board of Directors, Sub-Committees, Management, Employees, and Others 189 Board and the management. The Secretary of the Board of • Overseeing and advising the Board to ensure that Directors is also the accountable person in reviewing the directors perform their roles in compliance with relevant agenda and minutes of the Board’s meetings prior to their applicable laws, rules, and regulations as well as submission to the Board and managing documentation the Company’s objectives, Articles of Association, of the Share | J59: PTTEP one report 2023.pdf | K59: p. 179 | L59: https://sustainability.pttep.com/en/document/sustainability-reports | M59: No | O59: =IF(N59<>"",N59,G59) -> 0 | P59: Automated retrieval found a potentially relevant page, but the captured evidence did not contain all strict coding elements together. Conservatively coded 0 pending researcher verification.
A60: Thai Main Sample | B60: PTTEP | C60: 2023 | D60: Energy | E60: Q9 | F60: Measurable Progress Against Targets | G60: 0 | H60: AI preliminary 0/uncertain — researcher verification required | I60: PTTEP 100% 75% 51% 20% 15% 50% 100% 49% 25% 49% PTT PTT Energy PTTEP PTTEPI PTTEPO Siam Digital SPSE Complex EH GHBR 25% PTTEP 75% Structure and Business Operations Services 25% PTTEP 75% TC 50% 100% 53.9496% 25.001% 100% 80% 37.0842% 100% 100% 100% 100% 100% 100% 100% 100% 25% PTTEP 75% B8/32 PTTEP PTTEP PTTEP PTTEP PTTEP PTTEP PTTEP HK CPOC SHL Orange Partners PTTEPH ATL MGTC KV HV HL AG EP-Tech BC ED 25% SV 75% PTTEP 25% 28.5% 35% 100% NH 100% 100% PTTEP HV JOC HL JOC GBRS MENA PTTEP PGH HKO 50% Natuna 2 B.V. 100% 100% 1 | J60: PTTEP one report 2023.pdf | K60: p. 63 | L60: https://sustainability.pttep.com/en/document/sustainability-reports | M60: No | O60: =IF(N60<>"",N60,G60) -> 0 | P60: Quantitative emissions are present but measurable progress against a target/baseline/pathway was not sufficiently evidenced. | AI-assisted evidence retrieval; not yet personally verified by the researcher.
A61: Thai Main Sample | B61: PTTEP | C61: 2023 | D61: Energy | E61: Q10 | F61: Independent External Assurance | G61: 0 | H61: AI preliminary 0/uncertain — researcher verification required | I61: 56-1 One Report / Annual Report 2023 Sustainability Report Incorporated PTT Exploration and Production Public Company Limited 216 6.3.4 The Independent Directors Committee Report to the performance of the Board of Directors’ duties in 2023. Independent directors provided valuable opinions, Independent directors play a significant role in ensuring promoting transparency in both Board of Directors’ the best interests of the Company, shareholders, and meetings and subcommittees’ meetings. In the event that stakeholders. They ensure governance, policies, and a director is shown to have a conflict of interest with any strategies implementation, together wit | J61: PTTEP one report 2023.pdf | K61: p. 206 | L61: https://sustainability.pttep.com/en/document/sustainability-reports | M61: No | O61: =IF(N61<>"",N61,G61) -> 0 | P61: External audit/assurance language was found, but coverage of relevant GHG/climate data was not sufficiently clear. | AI-assisted evidence retrieval; not yet personally verified by the researcher.
A62: Thai Main Sample | B62: PTTEP | C62: 2024 | D62: Energy | E62: Q1 | F62: Time-Bound Net-Zero Target | G62: 1 | H62: 2024 pilot evidence pass: Verified | I62: PTTEP states Net Zero GHG Emissions for its E&P business by 2050, covering Scope 1 and 2 under operational control. | J62: PTTEP TCFD Report 2024 | K62: p.27 | L62: https://sustainability.pttep.com/storage/document/sustainability/pttep-tcfd-disclosure-report-en.pdf | M62: No | O62: =IF(N62<>"",N62,G62) -> 1 | P62: Explicit target and year. | Imported from the earlier 2024 evidence workbook; researcher personal verification is still required before treating this as final dissertation coding.
A63: Thai Main Sample | B63: PTTEP | C63: 2024 | D63: Energy | E63: Q2 | F63: Measurable Interim Emissions-Reduction Target | G63: 1 | H63: 2024 pilot evidence pass: Verified | I63: PTTEP targets a 30% reduction in GHG emissions intensity by 2030 and 50% by 2040 from 2020. | J63: PTTEP TCFD Report 2024 | K63: p.27 | L63: https://sustainability.pttep.com/storage/document/sustainability/pttep-tcfd-disclosure-report-en.pdf | M63: No | O63: =IF(N63<>"",N63,G63) -> 1 | P63: Quantitative interim target with baseline and target years. | Imported from the earlier 2024 evidence workbook; researcher personal verification is still required before treating this as final dissertation coding.
A64: Thai Main Sample | B64: PTTEP | C64: 2024 | D64: Energy | E64: Q3 | F64: SBTi-Validated Target | G64: 0 | H64: 2024 pilot evidence pass: Conservative 0 / dashboard recheck | I64: No validated entity-level SBTi target was confirmed for the 2024 observation. | J64: SBTi Target Dashboard | K64: Search PTTEP | L64: https://sciencebasedtargets.org/target-dashboard | M64: No | O64: =IF(N64<>"",N64,G64) -> 0 | P64: Oil & gas sector context and absence of confirmed validation; conservative 0. | Imported from the earlier 2024 evidence workbook; researcher personal verification is still required before treating this as final dissertation coding.
A65: Thai Main Sample | B65: PTTEP | C65: 2024 | D65: Energy | E65: Q4 | F65: Quantitative Scope 1 and Scope 2 Disclosure | G65: 1 | H65: 2024 pilot evidence pass: Verified | I65: PTTEP reports Scope 1 and Scope 2 emissions quantitatively in MtCO2e. | J65: PTTEP TCFD Report 2024 | K65: p.30 | L65: https://sustainability.pttep.com/storage/document/sustainability/pttep-tcfd-disclosure-report-en.pdf | M65: No | O65: =IF(N65<>"",N65,G65) -> 1 | P65: Quantitative Scope 1 and 2 with units. | Imported from the earlier 2024 evidence workbook; researcher personal verification is still required before treating this as final dissertation coding.
